[2015-09-24 17:39:16,460: WARNING/MainProcess] /usr/local/lib/python2.7/dist-packages/celery/apps/worker.py:161: CDeprecationWarning: 
Starting from version 3.2 Celery will refuse to accept pickle by default.

The pickle serializer is a security concern as it may give attackers
the ability to execute any command.  It's important to secure
your broker from unauthorized access when using pickle, so we think
that enabling pickle should require a deliberate action and not be
the default choice.

If you depend on pickle then you should set a setting to disable this
warning and to be sure that everything will continue working
when you upgrade to Celery 3.2::

    CELERY_ACCEPT_CONTENT = ['pickle', 'json', 'msgpack', 'yaml']

You must only enable the serializers that you will actually use.


  warnings.warn(CDeprecationWarning(W_PICKLE_DEPRECATED))
[2015-09-24 17:39:20,164: WARNING/MainProcess] celery@guang-VirtualBox ready.
Traceback (most recent call last):
  File "/usr/local/bin/celery", line 11, in <module>
    sys.exit(main())
  File "/usr/local/lib/python2.7/dist-packages/celery/__main__.py", line 30, in main
    main()
  File "/usr/local/lib/python2.7/dist-packages/celery/bin/celery.py", line 81, in main
    cmd.execute_from_commandline(argv)
  File "/usr/local/lib/python2.7/dist-packages/celery/bin/celery.py", line 769, in execute_from_commandline
    super(CeleryCommand, self).execute_from_commandline(argv)))
  File "/usr/local/lib/python2.7/dist-packages/celery/bin/base.py", line 309, in execute_from_commandline
    argv = self.setup_app_from_commandline(argv)
  File "/usr/local/lib/python2.7/dist-packages/celery/bin/base.py", line 469, in setup_app_from_commandline
    self.app = self.find_app(app)
  File "/usr/local/lib/python2.7/dist-packages/celery/bin/base.py", line 489, in find_app
    return find_app(app, symbol_by_name=self.symbol_by_name)
  File "/usr/local/lib/python2.7/dist-packages/celery/app/utils.py", line 229, in find_app
    sym = symbol_by_name(app, imp=imp)
  File "/usr/local/lib/python2.7/dist-packages/celery/bin/base.py", line 492, in symbol_by_name
    return symbol_by_name(name, imp=imp)
  File "/usr/local/lib/python2.7/dist-packages/kombu/utils/__init__.py", line 92, in symbol_by_name
    module = imp(module_name, package=package, **kwargs)
  File "/usr/local/lib/python2.7/dist-packages/celery/utils/imports.py", line 101, in import_from_cwd
    return imp(module, package=package)
  File "/usr/lib/python2.7/importlib/__init__.py", line 37, in import_module
    __import__(name)
  File "/home/ubuntu/mitm/tasks.py", line 73
SyntaxError: Non-ASCII character '\xe5' in file /home/ubuntu/mitm/tasks.py on line 73, but no encoding declared; see http://www.python.org/peps/pep-0263.html for details
[I 150924 19:09:34 command:113] Visit me at http://localhost:9000
[I 150924 19:09:34 command:115] Broker: redis://203.195.211.242:8090/0
[I 150924 19:09:34 command:118] Registered tasks: 
    ['celery.backend_cleanup',
     'celery.chain',
     'celery.chord',
     'celery.chord_unlock',
     'celery.chunks',
     'celery.group',
     'celery.map',
     'celery.starmap',
     'tasks.sqlmap_dispath']
[I 150924 19:09:34 mixins:225] Connected to redis://203.195.211.242:8090/0
[W 150924 19:09:38 control:44] 'stats' inspect method failed
[W 150924 19:09:38 control:44] 'active_queues' inspect method failed
[W 150924 19:09:38 control:44] 'registered' inspect method failed
[W 150924 19:09:38 control:44] 'scheduled' inspect method failed
[W 150924 19:09:38 control:44] 'active' inspect method failed
[W 150924 19:09:38 control:44] 'reserved' inspect method failed
[W 150924 19:09:38 control:44] 'revoked' inspect method failed
[W 150924 19:09:38 control:44] 'conf' inspect method failed
[2015-09-24 19:09:46,955: WARNING/MainProcess] /usr/local/lib/python2.7/dist-packages/celery/apps/worker.py:161: CDeprecationWarning: 
Starting from version 3.2 Celery will refuse to accept pickle by default.

The pickle serializer is a security concern as it may give attackers
the ability to execute any command.  It's important to secure
your broker from unauthorized access when using pickle, so we think
that enabling pickle should require a deliberate action and not be
the default choice.

If you depend on pickle then you should set a setting to disable this
warning and to be sure that everything will continue working
when you upgrade to Celery 3.2::

    CELERY_ACCEPT_CONTENT = ['pickle', 'json', 'msgpack', 'yaml']

You must only enable the serializers that you will actually use.


  warnings.warn(CDeprecationWarning(W_PICKLE_DEPRECATED))
[2015-09-24 19:09:48,137: WARNING/MainProcess] celery@VM-146-46-ubuntu ready.
[2015-09-24 19:09:49,079: ERROR/MainProcess] Task tasks.sqlmap_dispath[dff89a46-6de3-482c-aada-090ef28e65cb] raised unexpected: NameError("global name 'base64' is not defined",)
Traceback (most recent call last):
  File "/usr/local/lib/python2.7/dist-packages/celery/app/trace.py", line 240, in trace_task
    R = retval = fun(*args, **kwargs)
  File "/usr/local/lib/python2.7/dist-packages/celery/app/trace.py", line 438, in __protected_call__
    return self.run(*args, **kwargs)
  File "/home/ubuntu/mitm/tasks.py", line 59, in sqlmap_dispath
    cookie=base64.decodestring(cookie)
NameError: global name 'base64' is not defined
[2015-09-24 19:09:49,121: ERROR/MainProcess] Task tasks.sqlmap_dispath[52add511-7182-45dd-8809-2dd4d81a47c1] raised unexpected: NameError("global name 'base64' is not defined",)
Traceback (most recent call last):
  File "/usr/local/lib/python2.7/dist-packages/celery/app/trace.py", line 240, in trace_task
    R = retval = fun(*args, **kwargs)
  File "/usr/local/lib/python2.7/dist-packages/celery/app/trace.py", line 438, in __protected_call__
    return self.run(*args, **kwargs)
  File "/home/ubuntu/mitm/tasks.py", line 59, in sqlmap_dispath
    cookie=base64.decodestring(cookie)
NameError: global name 'base64' is not defined
[2015-09-24 19:09:49,142: ERROR/MainProcess] Task tasks.sqlmap_dispath[8c52a340-2e3f-43c2-a3ed-52550d2d9b72] raised unexpected: NameError("global name 'base64' is not defined",)
Traceback (most recent call last):
  File "/usr/local/lib/python2.7/dist-packages/celery/app/trace.py", line 240, in trace_task
    R = retval = fun(*args, **kwargs)
  File "/usr/local/lib/python2.7/dist-packages/celery/app/trace.py", line 438, in __protected_call__
    return self.run(*args, **kwargs)
  File "/home/ubuntu/mitm/tasks.py", line 59, in sqlmap_dispath
    cookie=base64.decodestring(cookie)
NameError: global name 'base64' is not defined
[2015-09-24 19:09:49,166: ERROR/MainProcess] Task tasks.sqlmap_dispath[69cc38bc-fb6c-49d2-9be5-052f33c0b51b] raised unexpected: NameError("global name 'base64' is not defined",)
Traceback (most recent call last):
  File "/usr/local/lib/python2.7/dist-packages/celery/app/trace.py", line 240, in trace_task
    R = retval = fun(*args, **kwargs)
  File "/usr/local/lib/python2.7/dist-packages/celery/app/trace.py", line 438, in __protected_call__
    return self.run(*args, **kwargs)
  File "/home/ubuntu/mitm/tasks.py", line 59, in sqlmap_dispath
    cookie=base64.decodestring(cookie)
NameError: global name 'base64' is not defined
[2015-09-24 19:09:49,184: ERROR/MainProcess] Task tasks.sqlmap_dispath[1a7528d7-6be2-41f1-8ff2-51cb703777eb] raised unexpected: NameError("global name 'base64' is not defined",)
Traceback (most recent call last):
  File "/usr/local/lib/python2.7/dist-packages/celery/app/trace.py", line 240, in trace_task
    R = retval = fun(*args, **kwargs)
  File "/usr/local/lib/python2.7/dist-packages/celery/app/trace.py", line 438, in __protected_call__
    return self.run(*args, **kwargs)
  File "/home/ubuntu/mitm/tasks.py", line 59, in sqlmap_dispath
    cookie=base64.decodestring(cookie)
NameError: global name 'base64' is not defined
[2015-09-24 19:09:49,202: ERROR/MainProcess] Task tasks.sqlmap_dispath[cc999ac5-d430-495e-b579-360658e08744] raised unexpected: NameError("global name 'base64' is not defined",)
Traceback (most recent call last):
  File "/usr/local/lib/python2.7/dist-packages/celery/app/trace.py", line 240, in trace_task
    R = retval = fun(*args, **kwargs)
  File "/usr/local/lib/python2.7/dist-packages/celery/app/trace.py", line 438, in __protected_call__
    return self.run(*args, **kwargs)
  File "/home/ubuntu/mitm/tasks.py", line 59, in sqlmap_dispath
    cookie=base64.decodestring(cookie)
NameError: global name 'base64' is not defined
[2015-09-24 19:09:49,220: ERROR/MainProcess] Task tasks.sqlmap_dispath[feb3d2ff-ff09-4d81-84e3-0917664c8fdb] raised unexpected: NameError("global name 'base64' is not defined",)
Traceback (most recent call last):
  File "/usr/local/lib/python2.7/dist-packages/celery/app/trace.py", line 240, in trace_task
    R = retval = fun(*args, **kwargs)
  File "/usr/local/lib/python2.7/dist-packages/celery/app/trace.py", line 438, in __protected_call__
    return self.run(*args, **kwargs)
  File "/home/ubuntu/mitm/tasks.py", line 59, in sqlmap_dispath
    cookie=base64.decodestring(cookie)
NameError: global name 'base64' is not defined
[2015-09-24 19:09:49,235: ERROR/MainProcess] Task tasks.sqlmap_dispath[b190d8f8-c3e7-4403-a9e1-76db2cada035] raised unexpected: NameError("global name 'base64' is not defined",)
Traceback (most recent call last):
  File "/usr/local/lib/python2.7/dist-packages/celery/app/trace.py", line 240, in trace_task
    R = retval = fun(*args, **kwargs)
  File "/usr/local/lib/python2.7/dist-packages/celery/app/trace.py", line 438, in __protected_call__
    return self.run(*args, **kwargs)
  File "/home/ubuntu/mitm/tasks.py", line 59, in sqlmap_dispath
    cookie=base64.decodestring(cookie)
NameError: global name 'base64' is not defined
[2015-09-24 19:09:49,254: ERROR/MainProcess] Task tasks.sqlmap_dispath[cf729484-bac1-4cad-a3fc-28987da7a5a6] raised unexpected: NameError("global name 'base64' is not defined",)
Traceback (most recent call last):
  File "/usr/local/lib/python2.7/dist-packages/celery/app/trace.py", line 240, in trace_task
    R = retval = fun(*args, **kwargs)
  File "/usr/local/lib/python2.7/dist-packages/celery/app/trace.py", line 438, in __protected_call__
    return self.run(*args, **kwargs)
  File "/home/ubuntu/mitm/tasks.py", line 59, in sqlmap_dispath
    cookie=base64.decodestring(cookie)
NameError: global name 'base64' is not defined
[2015-09-24 19:09:49,271: ERROR/MainProcess] Task tasks.sqlmap_dispath[e69e52f0-d3a4-4484-a0ee-12deab5a49ac] raised unexpected: NameError("global name 'base64' is not defined",)
Traceback (most recent call last):
  File "/usr/local/lib/python2.7/dist-packages/celery/app/trace.py", line 240, in trace_task
    R = retval = fun(*args, **kwargs)
  File "/usr/local/lib/python2.7/dist-packages/celery/app/trace.py", line 438, in __protected_call__
    return self.run(*args, **kwargs)
  File "/home/ubuntu/mitm/tasks.py", line 59, in sqlmap_dispath
    cookie=base64.decodestring(cookie)
NameError: global name 'base64' is not defined
[2015-09-24 19:09:49,287: ERROR/MainProcess] Task tasks.sqlmap_dispath[e274fd67-4aca-4e1d-adf2-9abf1909f539] raised unexpected: NameError("global name 'base64' is not defined",)
Traceback (most recent call last):
  File "/usr/local/lib/python2.7/dist-packages/celery/app/trace.py", line 240, in trace_task
    R = retval = fun(*args, **kwargs)
  File "/usr/local/lib/python2.7/dist-packages/celery/app/trace.py", line 438, in __protected_call__
    return self.run(*args, **kwargs)
  File "/home/ubuntu/mitm/tasks.py", line 59, in sqlmap_dispath
    cookie=base64.decodestring(cookie)
NameError: global name 'base64' is not defined
[2015-09-24 19:09:49,304: ERROR/MainProcess] Task tasks.sqlmap_dispath[bcae6c11-3488-491f-a7ea-23d173fad6cc] raised unexpected: NameError("global name 'base64' is not defined",)
Traceback (most recent call last):
  File "/usr/local/lib/python2.7/dist-packages/celery/app/trace.py", line 240, in trace_task
    R = retval = fun(*args, **kwargs)
  File "/usr/local/lib/python2.7/dist-packages/celery/app/trace.py", line 438, in __protected_call__
    return self.run(*args, **kwargs)
  File "/home/ubuntu/mitm/tasks.py", line 59, in sqlmap_dispath
    cookie=base64.decodestring(cookie)
NameError: global name 'base64' is not defined
[2015-09-24 19:09:49,324: ERROR/MainProcess] Task tasks.sqlmap_dispath[29feced1-4e4c-4e4b-b123-cb8a1a19d359] raised unexpected: NameError("global name 'base64' is not defined",)
Traceback (most recent call last):
  File "/usr/local/lib/python2.7/dist-packages/celery/app/trace.py", line 240, in trace_task
    R = retval = fun(*args, **kwargs)
  File "/usr/local/lib/python2.7/dist-packages/celery/app/trace.py", line 438, in __protected_call__
    return self.run(*args, **kwargs)
  File "/home/ubuntu/mitm/tasks.py", line 59, in sqlmap_dispath
    cookie=base64.decodestring(cookie)
NameError: global name 'base64' is not defined
[2015-09-24 19:09:49,339: ERROR/MainProcess] Task tasks.sqlmap_dispath[3553596f-875d-451a-88ee-1c04dd1d31ea] raised unexpected: NameError("global name 'base64' is not defined",)
Traceback (most recent call last):
  File "/usr/local/lib/python2.7/dist-packages/celery/app/trace.py", line 240, in trace_task
    R = retval = fun(*args, **kwargs)
  File "/usr/local/lib/python2.7/dist-packages/celery/app/trace.py", line 438, in __protected_call__
    return self.run(*args, **kwargs)
  File "/home/ubuntu/mitm/tasks.py", line 59, in sqlmap_dispath
    cookie=base64.decodestring(cookie)
NameError: global name 'base64' is not defined
[2015-09-24 19:09:49,350: ERROR/MainProcess] Task tasks.sqlmap_dispath[d804a1b2-ddb3-4d11-a9fd-395586b055ad] raised unexpected: NameError("global name 'base64' is not defined",)
Traceback (most recent call last):
  File "/usr/local/lib/python2.7/dist-packages/celery/app/trace.py", line 240, in trace_task
    R = retval = fun(*args, **kwargs)
  File "/usr/local/lib/python2.7/dist-packages/celery/app/trace.py", line 438, in __protected_call__
    return self.run(*args, **kwargs)
  File "/home/ubuntu/mitm/tasks.py", line 59, in sqlmap_dispath
    cookie=base64.decodestring(cookie)
NameError: global name 'base64' is not defined
[2015-09-24 19:09:49,359: ERROR/MainProcess] Task tasks.sqlmap_dispath[4cce90f1-cbe3-4b99-ad73-156d99040faa] raised unexpected: NameError("global name 'base64' is not defined",)
Traceback (most recent call last):
  File "/usr/local/lib/python2.7/dist-packages/celery/app/trace.py", line 240, in trace_task
    R = retval = fun(*args, **kwargs)
  File "/usr/local/lib/python2.7/dist-packages/celery/app/trace.py", line 438, in __protected_call__
    return self.run(*args, **kwargs)
  File "/home/ubuntu/mitm/tasks.py", line 59, in sqlmap_dispath
    cookie=base64.decodestring(cookie)
NameError: global name 'base64' is not defined
[I 150924 19:09:51 web:1908] 200 GET /dashboard (106.39.10.162) 46.27ms
[I 150924 19:09:54 web:1908] 304 GET /dashboard (106.39.10.162) 10.87ms
[I 150924 19:10:08 web:1908] 200 GET /dashboard (106.39.10.162) 9.63ms
[I 150924 19:10:10 web:1908] 304 GET /dashboard (106.39.10.162) 10.79ms
[I 150924 19:10:49 web:1908] 200 POST /api/task/async-apply/tasks.sqlmap_dispath (106.39.10.162) 16.85ms
[2015-09-24 19:10:49,639: ERROR/MainProcess] Task tasks.sqlmap_dispath[47bef70b-9ba5-4050-bc46-fce41edf06aa] raised unexpected: NameError("global name 'base64' is not defined",)
Traceback (most recent call last):
  File "/usr/local/lib/python2.7/dist-packages/celery/app/trace.py", line 240, in trace_task
    R = retval = fun(*args, **kwargs)
  File "/usr/local/lib/python2.7/dist-packages/celery/app/trace.py", line 438, in __protected_call__
    return self.run(*args, **kwargs)
  File "/home/ubuntu/mitm/tasks.py", line 59, in sqlmap_dispath
    cookie=base64.decodestring(cookie)
NameError: global name 'base64' is not defined
[I 150924 19:11:12 web:1908] 200 POST /api/task/async-apply/tasks.sqlmap_dispath (106.39.10.162) 8.49ms
[2015-09-24 19:11:12,644: ERROR/MainProcess] Task tasks.sqlmap_dispath[04b662f7-4a98-4500-9164-3eeb0090b2be] raised unexpected: NameError("global name 'base64' is not defined",)
Traceback (most recent call last):
  File "/usr/local/lib/python2.7/dist-packages/celery/app/trace.py", line 240, in trace_task
    R = retval = fun(*args, **kwargs)
  File "/usr/local/lib/python2.7/dist-packages/celery/app/trace.py", line 438, in __protected_call__
    return self.run(*args, **kwargs)
  File "/home/ubuntu/mitm/tasks.py", line 59, in sqlmap_dispath
    cookie=base64.decodestring(cookie)
NameError: global name 'base64' is not defined
[I 150924 19:11:24 web:1908] 200 GET /dashboard (106.39.10.162) 11.02ms
[I 150924 19:11:26 web:1908] 200 GET /tasks?limit=100&state=FAILURE (106.39.10.162) 66.11ms
[I 150924 19:13:18 command:85] SIGTERM detected, shutting down

worker: Warm shutdown (MainProcess)
 
 -------------- celery@VM-146-46-ubuntu v3.1.18 (Cipater)
---- **** ----- 
--- * ***  * -- Linux-3.13.0-36-generic-i686-with-Ubuntu-14.04-trusty
-- * - **** --- 
- ** ---------- [config]
- ** ---------- .> app:         __main__:0xb693ce6c
- ** ---------- .> transport:   redis://203.195.211.242:8090/0
- ** ---------- .> results:     disabled
- *** --- * --- .> concurrency: 1 (prefork)
-- ******* ---- 
--- ***** ----- [queues]
 -------------- .> celery           exchange=celery(direct) key=celery
                

[2015-09-24 19:13:30,834: WARNING/MainProcess] /usr/local/lib/python2.7/dist-packages/celery/apps/worker.py:161: CDeprecationWarning: 
Starting from version 3.2 Celery will refuse to accept pickle by default.

The pickle serializer is a security concern as it may give attackers
the ability to execute any command.  It's important to secure
your broker from unauthorized access when using pickle, so we think
that enabling pickle should require a deliberate action and not be
the default choice.

If you depend on pickle then you should set a setting to disable this
warning and to be sure that everything will continue working
when you upgrade to Celery 3.2::

    CELERY_ACCEPT_CONTENT = ['pickle', 'json', 'msgpack', 'yaml']

You must only enable the serializers that you will actually use.


  warnings.warn(CDeprecationWarning(W_PICKLE_DEPRECATED))
[2015-09-24 19:13:32,011: WARNING/MainProcess] celery@VM-146-46-ubuntu ready.
[I 150924 19:13:39 command:113] Visit me at http://localhost:9000
[I 150924 19:13:39 command:115] Broker: redis://203.195.211.242:8090/0
[I 150924 19:13:39 command:118] Registered tasks: 
    ['celery.backend_cleanup',
     'celery.chain',
     'celery.chord',
     'celery.chord_unlock',
     'celery.chunks',
     'celery.group',
     'celery.map',
     'celery.starmap',
     'tasks.sqlmap_dispath']
[I 150924 19:13:39 mixins:225] Connected to redis://203.195.211.242:8090/0
[I 150924 19:13:43 web:1908] 200 GET /dashboard (106.39.10.162) 57.48ms
[I 150924 19:13:51 web:1908] 200 GET /dashboard (106.39.10.162) 10.99ms
[I 150924 19:13:59 web:1908] 200 POST /api/task/async-apply/tasks.sqlmap_dispath (106.39.10.162) 17.31ms
[2015-09-24 19:13:59,566: ERROR/MainProcess] Task tasks.sqlmap_dispath[c0edf64d-1271-4f9b-bd93-8b2a802f42a2] raised unexpected: Error('Incorrect padding',)
Traceback (most recent call last):
  File "/usr/local/lib/python2.7/dist-packages/celery/app/trace.py", line 240, in trace_task
    R = retval = fun(*args, **kwargs)
  File "/usr/local/lib/python2.7/dist-packages/celery/app/trace.py", line 438, in __protected_call__
    return self.run(*args, **kwargs)
  File "/home/ubuntu/mitm/tasks.py", line 62, in sqlmap_dispath
    data=base64.decodestring(data)
  File "/usr/lib/python2.7/base64.py", line 321, in decodestring
    return binascii.a2b_base64(s)
Error: Incorrect padding
[I 150924 19:14:00 web:1908] 200 GET /dashboard (106.39.10.162) 10.84ms
[I 150924 19:14:01 web:1908] 200 GET /tasks?limit=100&state=FAILURE (106.39.10.162) 56.62ms
[I 150924 19:14:20 http1connection:253] Malformed HTTP message from 113.108.0.27: Malformed HTTP request line
[I 150924 19:14:21 web:1908] 200 GET / (113.108.0.27) 15.32ms
[I 150924 19:16:11 web:1908] 200 POST /api/task/async-apply/tasks.sqlmap_dispath (106.39.10.162) 8.55ms
[I 150924 19:16:12 web:1908] 200 GET /dashboard (106.39.10.162) 27.59ms
[I 150924 19:16:20 web:1908] 200 POST /api/task/async-apply/tasks.sqlmap_dispath (106.39.10.162) 52.94ms
[I 150924 19:16:26 web:1908] 200 POST /api/task/async-apply/tasks.sqlmap_dispath (106.39.10.162) 53.81ms
[I 150924 19:17:12 web:1908] 200 POST /api/task/async-apply/tasks.sqlmap_dispath (106.39.10.162) 51.64ms
[I 150924 19:17:34 web:1908] 200 GET /dashboard (106.39.10.162) 14.86ms
[I 150924 19:17:40 web:1908] 200 GET /tasks?limit=100&state=FAILURE (106.39.10.162) 2.42ms
[I 150924 19:19:39 web:1908] 200 GET /tasks?limit=100&state=FAILURE (106.39.10.162) 2.24ms
[I 150924 19:19:40 web:1908] 200 GET /dashboard (106.39.10.162) 6.41ms
[I 150924 19:19:41 web:1908] 304 GET /dashboard (106.39.10.162) 20.56ms
[I 150924 19:19:42 web:1908] 200 GET /tasks?limit=100 (106.39.10.162) 4.00ms
[I 150924 19:22:26 web:1908] 200 GET /dashboard (106.39.10.162) 16.05ms
[I 150924 19:22:29 web:1908] 200 GET /tasks?limit=100 (106.39.10.162) 3.37ms
[I 150924 19:22:50 web:1908] 200 GET /dashboard (106.39.10.162) 10.95ms
[I 150924 19:31:26 web:1908] 200 GET /dashboard (106.39.10.162) 22.59ms
[I 150924 19:31:28 web:1908] 200 GET /dashboard (106.39.10.162) 17.32ms
[I 150924 19:32:50 web:1908] 200 GET /dashboard (106.39.10.162) 10.51ms
[I 150924 19:33:01 web:1908] 200 POST /api/task/async-apply/tasks.sqlmap_dispath (106.39.10.162) 12.24ms
[I 150924 19:33:09 web:1908] 200 POST /api/task/async-apply/tasks.sqlmap_dispath (106.39.10.162) 132.34ms
[I 150924 19:33:32 web:1908] 200 GET /tasks?limit=100 (106.39.10.162) 3.28ms
[I 150924 19:33:33 web:1908] 200 GET /dashboard (106.39.10.162) 11.35ms
[I 150924 19:33:35 web:1908] 304 GET /dashboard (106.39.10.162) 17.76ms

worker: Warm shutdown (MainProcess)
[2015-09-24 19:34:04,064: ERROR/MainProcess] Process 'Worker-1' pid:11822 exited with 'signal 15 (SIGTERM)'
[2015-09-24 19:34:04,080: ERROR/MainProcess] Task tasks.sqlmap_dispath[218b605e-99d1-4be0-8c77-f42ab706e63f] raised unexpected: WorkerLostError('Worker exited prematurely: signal 15 (SIGTERM).',)
Traceback (most recent call last):
  File "/usr/local/lib/python2.7/dist-packages/billiard/pool.py", line 1171, in mark_as_worker_lost
    human_status(exitcode)),
WorkerLostError: Worker exited prematurely: signal 15 (SIGTERM).
[2015-09-24 19:34:04,081: WARNING/MainProcess] Restoring 3 unacknowledged message(s).
 
 -------------- celery@VM-146-46-ubuntu v3.1.18 (Cipater)
---- **** ----- 
--- * ***  * -- Linux-3.13.0-36-generic-i686-with-Ubuntu-14.04-trusty
-- * - **** --- 
- ** ---------- [config]
- ** ---------- .> app:         __main__:0xb68cde4c
- ** ---------- .> transport:   redis://203.195.211.242:8090/0
- ** ---------- .> results:     disabled
- *** --- * --- .> concurrency: 1 (prefork)
-- ******* ---- 
--- ***** ----- [queues]
 -------------- .> celery           exchange=celery(direct) key=celery
                

[2015-09-24 19:34:16,148: WARNING/MainProcess] /usr/local/lib/python2.7/dist-packages/celery/apps/worker.py:161: CDeprecationWarning: 
Starting from version 3.2 Celery will refuse to accept pickle by default.

The pickle serializer is a security concern as it may give attackers
the ability to execute any command.  It's important to secure
your broker from unauthorized access when using pickle, so we think
that enabling pickle should require a deliberate action and not be
the default choice.

If you depend on pickle then you should set a setting to disable this
warning and to be sure that everything will continue working
when you upgrade to Celery 3.2::

    CELERY_ACCEPT_CONTENT = ['pickle', 'json', 'msgpack', 'yaml']

You must only enable the serializers that you will actually use.


  warnings.warn(CDeprecationWarning(W_PICKLE_DEPRECATED))
[2015-09-24 19:34:17,328: WARNING/MainProcess] celery@VM-146-46-ubuntu ready.
[I 150924 19:34:26 web:1908] 200 GET /dashboard (106.39.10.162) 6.51ms
[I 150924 19:34:29 web:1908] 200 GET /tasks?limit=100&state=FAILURE (106.39.10.162) 8.84ms
[I 150924 19:34:39 web:1908] 200 GET /dashboard (106.39.10.162) 19.37ms
[I 150924 19:36:17 web:1908] 200 GET /dashboard (106.39.10.162) 17.96ms
[I 150924 19:36:20 web:1908] 304 GET /dashboard (106.39.10.162) 10.91ms
[I 150924 19:36:24 web:1908] 200 GET /dashboard (106.39.10.162) 11.37ms
[I 150924 19:36:32 web:1908] 200 GET /dashboard (106.39.10.162) 18.61ms
[I 150924 19:37:26 web:1908] 200 GET /dashboard (106.39.10.162) 14.89ms
[2015-09-24 19:42:53,900: WARNING/Worker-1] {u'data': [], u'success': True, u'error': []}
[2015-09-24 19:59:57,440: WARNING/Worker-1] {u'data': [], u'success': True, u'error': []}
[2015-09-24 20:02:04,644: WARNING/Worker-1] {u'data': [], u'success': True, u'error': []}
[I 150924 20:05:13 web:1908] 200 GET /dashboard (106.39.10.162) 11.47ms
[I 150924 20:05:14 web:1908] 200 GET /tasks?limit=100&state=SUCCESS (106.39.10.162) 3.85ms
[I 150924 20:15:15 web:1908] 200 GET /dashboard (106.39.10.162) 10.45ms
[I 150924 20:15:17 web:1908] 200 GET /tasks?limit=100&state=SUCCESS (106.39.10.162) 2.68ms
